{
 "cells": [
  {
   "cell_type": "code",
   "execution_count": 1,
   "id": "81835749",
   "metadata": {},
   "outputs": [
    {
     "name": "stderr",
     "output_type": "stream",
     "text": [
      "/root/sj_Trading/.venv/lib/python3.11/site-packages/tqdm/auto.py:21: TqdmWarning: IProgress not found. Please update jupyter and ipywidgets. See https://ipywidgets.readthedocs.io/en/stable/user_install.html\n",
      "  from .autonotebook import tqdm as notebook_tqdm\n"
     ]
    }
   ],
   "source": [
    "import os\n",
    "from langchain_community.llms import VLLM\n",
    "from huggingface_hub import login\n",
    "from dotenv import load_dotenv\n",
    "\n",
    "load_dotenv()\n",
    "\n",
    "hf_token = os.getenv('hf_token')\n",
    "login(token=hf_token)"
   ]
  },
  {
   "cell_type": "code",
   "execution_count": null,
   "id": "4a9dafc1",
   "metadata": {},
   "outputs": [
    {
     "name": "stdout",
     "output_type": "stream",
     "text": [
      "INFO 06-13 16:27:59 [__init__.py:243] Automatically detected platform cuda.\n"
     ]
    },
    {
     "name": "stderr",
     "output_type": "stream",
     "text": [
      "2025-06-13 16:28:02,490\tINFO util.py:154 -- Missing packages: ['ipywidgets']. Run `pip install -U ipywidgets`, then restart the notebook server for rich notebook output.\n"
     ]
    },
    {
     "name": "stdout",
     "output_type": "stream",
     "text": [
      "INFO 06-13 16:28:02 [__init__.py:31] Available plugins for group vllm.general_plugins:\n",
      "INFO 06-13 16:28:02 [__init__.py:33] - lora_filesystem_resolver -> vllm.plugins.lora_resolvers.filesystem_resolver:register_filesystem_resolver\n",
      "INFO 06-13 16:28:02 [__init__.py:36] All plugins in this group will be loaded. Set `VLLM_PLUGINS` to control which plugins to load.\n",
      "ERROR 06-13 16:28:03 [config.py:107] Error retrieving file list: 404 Client Error. (Request ID: Root=1-684c5110-1e3d158e685ae1c63aa80f17;8ae1fe10-533e-4877-9e1b-7a0be2e999e4)\n",
      "ERROR 06-13 16:28:03 [config.py:107] \n",
      "ERROR 06-13 16:28:03 [config.py:107] Repository Not Found for url: https://huggingface.co/api/models/model_name/tree/main?recursive=True&expand=False.\n",
      "ERROR 06-13 16:28:03 [config.py:107] Please make sure you specified the correct `repo_id` and `repo_type`.\n",
      "ERROR 06-13 16:28:03 [config.py:107] If you are trying to access a private or gated repo, make sure you are authenticated. For more details, see https://huggingface.co/docs/huggingface_hub/authentication, retrying 1 of 2\n",
      "ERROR 06-13 16:28:05 [config.py:105] Error retrieving file list: 404 Client Error. (Request ID: Root=1-684c5112-71b71d675b5b4e5108d8b86f;e30105a2-acf0-4d11-a38b-1b7a173af03c)\n",
      "ERROR 06-13 16:28:05 [config.py:105] \n",
      "ERROR 06-13 16:28:05 [config.py:105] Repository Not Found for url: https://huggingface.co/api/models/model_name/tree/main?recursive=True&expand=False.\n",
      "ERROR 06-13 16:28:05 [config.py:105] Please make sure you specified the correct `repo_id` and `repo_type`.\n",
      "ERROR 06-13 16:28:05 [config.py:105] If you are trying to access a private or gated repo, make sure you are authenticated. For more details, see https://huggingface.co/docs/huggingface_hub/authentication\n"
     ]
    },
    {
     "ename": "ValidationError",
     "evalue": "1 validation error for VLLM\n  Value error, Invalid repository ID or local directory specified: 'model_name'.\nPlease verify the following requirements:\n1. Provide a valid Hugging Face repository ID.\n2. Specify a local directory that contains a recognized configuration file.\n   - For Hugging Face models: ensure the presence of a 'config.json'.\n   - For Mistral models: ensure the presence of a 'params.json'.\n3. For GGUF: pass the local path of the GGUF checkpoint.\n   Loading GGUF from a remote repo directly is not yet supported.\n [type=value_error, input_value={'model': 'model_name', '...gs': {}, 'client': None}, input_type=dict]\n    For further information visit https://errors.pydantic.dev/2.11/v/value_error",
     "output_type": "error",
     "traceback": [
      "\u001b[31m---------------------------------------------------------------------------\u001b[39m",
      "\u001b[31mValidationError\u001b[39m                           Traceback (most recent call last)",
      "\u001b[36mCell\u001b[39m\u001b[36m \u001b[39m\u001b[32mIn[2]\u001b[39m\u001b[32m, line 1\u001b[39m\n\u001b[32m----> \u001b[39m\u001b[32m1\u001b[39m llm = \u001b[43mVLLM\u001b[49m\u001b[43m(\u001b[49m\n\u001b[32m      2\u001b[39m \u001b[43m    \u001b[49m\u001b[43mmodel\u001b[49m\u001b[43m=\u001b[49m\u001b[33;43m\"\u001b[39;49m\u001b[33;43mmodel_name\u001b[39;49m\u001b[33;43m\"\u001b[39;49m\u001b[43m,\u001b[49m\n\u001b[32m      3\u001b[39m \u001b[43m    \u001b[49m\u001b[43mtoken\u001b[49m\u001b[43m=\u001b[49m\u001b[43mhf_token\u001b[49m\u001b[43m,\u001b[49m\n\u001b[32m      4\u001b[39m \u001b[43m    \u001b[49m\u001b[43mtrust_remote_code\u001b[49m\u001b[43m=\u001b[49m\u001b[38;5;28;43;01mTrue\u001b[39;49;00m\u001b[43m,\u001b[49m\n\u001b[32m      5\u001b[39m \u001b[43m    \u001b[49m\u001b[43mmax_new_tokens\u001b[49m\u001b[43m=\u001b[49m\u001b[32;43m128\u001b[39;49m\u001b[43m,\u001b[49m\n\u001b[32m      6\u001b[39m \u001b[43m    \u001b[49m\u001b[43mtop_k\u001b[49m\u001b[43m=\u001b[49m\u001b[32;43m10\u001b[39;49m\u001b[43m,\u001b[49m\n\u001b[32m      7\u001b[39m \u001b[43m    \u001b[49m\u001b[43mtop_p\u001b[49m\u001b[43m=\u001b[49m\u001b[32;43m0.95\u001b[39;49m\u001b[43m,\u001b[49m\n\u001b[32m      8\u001b[39m \u001b[43m    \u001b[49m\u001b[43mtemperature\u001b[49m\u001b[43m=\u001b[49m\u001b[32;43m0.8\u001b[39;49m\u001b[43m,\u001b[49m\n\u001b[32m      9\u001b[39m \u001b[43m)\u001b[49m\n\u001b[32m     11\u001b[39m \u001b[38;5;28mprint\u001b[39m(llm.invoke(\u001b[33m\"\u001b[39m\u001b[33mWhat is the capital of France?\u001b[39m\u001b[33m\"\u001b[39m))\n",
      "\u001b[36mFile \u001b[39m\u001b[32m~/sj_Trading/.venv/lib/python3.11/site-packages/langchain_core/load/serializable.py:130\u001b[39m, in \u001b[36mSerializable.__init__\u001b[39m\u001b[34m(self, *args, **kwargs)\u001b[39m\n\u001b[32m    128\u001b[39m \u001b[38;5;28;01mdef\u001b[39;00m\u001b[38;5;250m \u001b[39m\u001b[34m__init__\u001b[39m(\u001b[38;5;28mself\u001b[39m, *args: Any, **kwargs: Any) -> \u001b[38;5;28;01mNone\u001b[39;00m:\n\u001b[32m    129\u001b[39m \u001b[38;5;250m    \u001b[39m\u001b[33;03m\"\"\"\"\"\"\u001b[39;00m  \u001b[38;5;66;03m# noqa: D419\u001b[39;00m\n\u001b[32m--> \u001b[39m\u001b[32m130\u001b[39m     \u001b[38;5;28;43msuper\u001b[39;49m\u001b[43m(\u001b[49m\u001b[43m)\u001b[49m\u001b[43m.\u001b[49m\u001b[34;43m__init__\u001b[39;49m\u001b[43m(\u001b[49m\u001b[43m*\u001b[49m\u001b[43margs\u001b[49m\u001b[43m,\u001b[49m\u001b[43m \u001b[49m\u001b[43m*\u001b[49m\u001b[43m*\u001b[49m\u001b[43mkwargs\u001b[49m\u001b[43m)\u001b[49m\n",
      "\u001b[36mFile \u001b[39m\u001b[32m~/sj_Trading/.venv/lib/python3.11/site-packages/pydantic/main.py:253\u001b[39m, in \u001b[36mBaseModel.__init__\u001b[39m\u001b[34m(self, **data)\u001b[39m\n\u001b[32m    251\u001b[39m \u001b[38;5;66;03m# `__tracebackhide__` tells pytest and some other tools to omit this function from tracebacks\u001b[39;00m\n\u001b[32m    252\u001b[39m __tracebackhide__ = \u001b[38;5;28;01mTrue\u001b[39;00m\n\u001b[32m--> \u001b[39m\u001b[32m253\u001b[39m validated_self = \u001b[38;5;28;43mself\u001b[39;49m\u001b[43m.\u001b[49m\u001b[43m__pydantic_validator__\u001b[49m\u001b[43m.\u001b[49m\u001b[43mvalidate_python\u001b[49m\u001b[43m(\u001b[49m\u001b[43mdata\u001b[49m\u001b[43m,\u001b[49m\u001b[43m \u001b[49m\u001b[43mself_instance\u001b[49m\u001b[43m=\u001b[49m\u001b[38;5;28;43mself\u001b[39;49m\u001b[43m)\u001b[49m\n\u001b[32m    254\u001b[39m \u001b[38;5;28;01mif\u001b[39;00m \u001b[38;5;28mself\u001b[39m \u001b[38;5;129;01mis\u001b[39;00m \u001b[38;5;129;01mnot\u001b[39;00m validated_self:\n\u001b[32m    255\u001b[39m     warnings.warn(\n\u001b[32m    256\u001b[39m         \u001b[33m'\u001b[39m\u001b[33mA custom validator is returning a value other than `self`.\u001b[39m\u001b[38;5;130;01m\\n\u001b[39;00m\u001b[33m'\u001b[39m\n\u001b[32m    257\u001b[39m         \u001b[33m\"\u001b[39m\u001b[33mReturning anything other than `self` from a top level model validator isn\u001b[39m\u001b[33m'\u001b[39m\u001b[33mt supported when validating via `__init__`.\u001b[39m\u001b[38;5;130;01m\\n\u001b[39;00m\u001b[33m\"\u001b[39m\n\u001b[32m    258\u001b[39m         \u001b[33m'\u001b[39m\u001b[33mSee the `model_validator` docs (https://docs.pydantic.dev/latest/concepts/validators/#model-validators) for more details.\u001b[39m\u001b[33m'\u001b[39m,\n\u001b[32m    259\u001b[39m         stacklevel=\u001b[32m2\u001b[39m,\n\u001b[32m    260\u001b[39m     )\n",
      "\u001b[31mValidationError\u001b[39m: 1 validation error for VLLM\n  Value error, Invalid repository ID or local directory specified: 'model_name'.\nPlease verify the following requirements:\n1. Provide a valid Hugging Face repository ID.\n2. Specify a local directory that contains a recognized configuration file.\n   - For Hugging Face models: ensure the presence of a 'config.json'.\n   - For Mistral models: ensure the presence of a 'params.json'.\n3. For GGUF: pass the local path of the GGUF checkpoint.\n   Loading GGUF from a remote repo directly is not yet supported.\n [type=value_error, input_value={'model': 'model_name', '...gs': {}, 'client': None}, input_type=dict]\n    For further information visit https://errors.pydantic.dev/2.11/v/value_error"
     ]
    }
   ],
   "source": [
    "llm = VLLM(\n",
    "    model=\"mistralai/Mistral-7B-Instruct-v0.3\",\n",
    "    token=hf_token,\n",
    "    trust_remote_code=True,\n",
    "    max_new_tokens=128,\n",
    "    top_k=10,\n",
    "    top_p=0.95,\n",
    "    temperature=0.8,\n",
    ")\n",
    "\n",
    "print(llm.invoke(\"What is the capital of France?\"))"
   ]
  }
 ],
 "metadata": {
  "kernelspec": {
   "display_name": ".venv",
   "language": "python",
   "name": "python3"
  },
  "language_info": {
   "codemirror_mode": {
    "name": "ipython",
    "version": 3
   },
   "file_extension": ".py",
   "mimetype": "text/x-python",
   "name": "python",
   "nbconvert_exporter": "python",
   "pygments_lexer": "ipython3",
   "version": "3.11.13"
  }
 },
 "nbformat": 4,
 "nbformat_minor": 5
}
